
2024-12-16 09:06:38.934534: (sqlite3.IntegrityError) NOT NULL constraint failed: user.name
[SQL: INSERT INTO user (email, password_hash, name, photo_path, is_admin) VALUES (?, ?, ?, ?, ?)]
[parameters: ('tt@2cconseil.com', 'pbkdf2:sha256:600000$jC4in2YWgjB5RkaF$c39eb7dd6017d4298167ba2d9539d488ad6ea5e2afa00d39220ea2a7e6e6db99', None, None, 0)]
(Background on this error at: https://sqlalche.me/e/20/gkpj)
Traceback (most recent call last):
  File "C:\Users\hmbegham\AppData\Roaming\Python\Python312\site-packages\sqlalchemy\engine\base.py", line 1965, in _exec_single_context
    self.dialect.do_execute(
  File "C:\Users\hmbegham\AppData\Roaming\Python\Python312\site-packages\sqlalchemy\engine\default.py", line 921, in do_execute
    cursor.execute(statement, parameters)
sqlite3.IntegrityError: NOT NULL constraint failed: user.name

The above exception was the direct cause of the following exception:

Traceback (most recent call last):
  File "C:\Users\hmbegham\AppData\Roaming\Python\Python312\site-packages\flask\app.py", line 1484, in full_dispatch_request
    rv = self.dispatch_request()
         ^^^^^^^^^^^^^^^^^^^^^^^
  File "C:\Users\hmbegham\AppData\Roaming\Python\Python312\site-packages\flask\app.py", line 1469, in dispatch_request
    return self.ensure_sync(self.view_functions[rule.endpoint])(**view_args)
           ^^^^^^^^^^^^^^^^^^^^^^^^^^^^^^^^^^^^^^^^^^^^^^^^^^^^^^^^^^^^^^^^^
  File "C:\Users\hmbegham\git\employee_vote_app\app.py", line 183, in signup
    db.session.commit()
  File "C:\Users\hmbegham\AppData\Roaming\Python\Python312\site-packages\sqlalchemy\orm\scoping.py", line 554, in commit
    return self._proxied.commit()
           ^^^^^^^^^^^^^^^^^^^^^^
  File "C:\Users\hmbegham\AppData\Roaming\Python\Python312\site-packages\sqlalchemy\orm\session.py", line 1923, in commit
    trans.commit(_to_root=True)
  File "<string>", line 2, in commit
  File "C:\Users\hmbegham\AppData\Roaming\Python\Python312\site-packages\sqlalchemy\orm\state_changes.py", line 139, in _go
    ret_value = fn(self, *arg, **kw)
                ^^^^^^^^^^^^^^^^^^^^
  File "C:\Users\hmbegham\AppData\Roaming\Python\Python312\site-packages\sqlalchemy\orm\session.py", line 1239, in commit
    self._prepare_impl()
  File "<string>", line 2, in _prepare_impl
  File "C:\Users\hmbegham\AppData\Roaming\Python\Python312\site-packages\sqlalchemy\orm\state_changes.py", line 139, in _go
    ret_value = fn(self, *arg, **kw)
                ^^^^^^^^^^^^^^^^^^^^
  File "C:\Users\hmbegham\AppData\Roaming\Python\Python312\site-packages\sqlalchemy\orm\session.py", line 1214, in _prepare_impl
    self.session.flush()
  File "C:\Users\hmbegham\AppData\Roaming\Python\Python312\site-packages\sqlalchemy\orm\session.py", line 4179, in flush
    self._flush(objects)
  File "C:\Users\hmbegham\AppData\Roaming\Python\Python312\site-packages\sqlalchemy\orm\session.py", line 4314, in _flush
    with util.safe_reraise():
  File "C:\Users\hmbegham\AppData\Roaming\Python\Python312\site-packages\sqlalchemy\util\langhelpers.py", line 146, in __exit__
    raise exc_value.with_traceback(exc_tb)
  File "C:\Users\hmbegham\AppData\Roaming\Python\Python312\site-packages\sqlalchemy\orm\session.py", line 4275, in _flush
    flush_context.execute()
  File "C:\Users\hmbegham\AppData\Roaming\Python\Python312\site-packages\sqlalchemy\orm\unitofwork.py", line 466, in execute
    rec.execute(self)
  File "C:\Users\hmbegham\AppData\Roaming\Python\Python312\site-packages\sqlalchemy\orm\unitofwork.py", line 642, in execute
    util.preloaded.orm_persistence.save_obj(
  File "C:\Users\hmbegham\AppData\Roaming\Python\Python312\site-packages\sqlalchemy\orm\persistence.py", line 93, in save_obj
    _emit_insert_statements(
  File "C:\Users\hmbegham\AppData\Roaming\Python\Python312\site-packages\sqlalchemy\orm\persistence.py", line 1226, in _emit_insert_statements
    result = connection.execute(
             ^^^^^^^^^^^^^^^^^^^
  File "C:\Users\hmbegham\AppData\Roaming\Python\Python312\site-packages\sqlalchemy\engine\base.py", line 1412, in execute
    return meth(
           ^^^^^
  File "C:\Users\hmbegham\AppData\Roaming\Python\Python312\site-packages\sqlalchemy\sql\elements.py", line 516, in _execute_on_connection
    return connection._execute_clauseelement(
           ^^^^^^^^^^^^^^^^^^^^^^^^^^^^^^^^^^
  File "C:\Users\hmbegham\AppData\Roaming\Python\Python312\site-packages\sqlalchemy\engine\base.py", line 1635, in _execute_clauseelement
    ret = self._execute_context(
          ^^^^^^^^^^^^^^^^^^^^^^
  File "C:\Users\hmbegham\AppData\Roaming\Python\Python312\site-packages\sqlalchemy\engine\base.py", line 1844, in _execute_context
    return self._exec_single_context(
           ^^^^^^^^^^^^^^^^^^^^^^^^^^
  File "C:\Users\hmbegham\AppData\Roaming\Python\Python312\site-packages\sqlalchemy\engine\base.py", line 1984, in _exec_single_context
    self._handle_dbapi_exception(
  File "C:\Users\hmbegham\AppData\Roaming\Python\Python312\site-packages\sqlalchemy\engine\base.py", line 2339, in _handle_dbapi_exception
    raise sqlalchemy_exception.with_traceback(exc_info[2]) from e
  File "C:\Users\hmbegham\AppData\Roaming\Python\Python312\site-packages\sqlalchemy\engine\base.py", line 1965, in _exec_single_context
    self.dialect.do_execute(
  File "C:\Users\hmbegham\AppData\Roaming\Python\Python312\site-packages\sqlalchemy\engine\default.py", line 921, in do_execute
    cursor.execute(statement, parameters)
sqlalchemy.exc.IntegrityError: (sqlite3.IntegrityError) NOT NULL constraint failed: user.name
[SQL: INSERT INTO user (email, password_hash, name, photo_path, is_admin) VALUES (?, ?, ?, ?, ?)]
[parameters: ('tt@2cconseil.com', 'pbkdf2:sha256:600000$jC4in2YWgjB5RkaF$c39eb7dd6017d4298167ba2d9539d488ad6ea5e2afa00d39220ea2a7e6e6db99', None, None, 0)]
(Background on this error at: https://sqlalche.me/e/20/gkpj)

2024-12-16 09:32:58.489854: (sqlite3.OperationalError) no such column: user.first_name
[SQL: SELECT user.id AS user_id, user.email AS user_email, user.name AS user_name, user.first_name AS user_first_name, user.last_name AS user_last_name, user.password_hash AS user_password_hash, user.photo_path AS user_photo_path, user.is_admin AS user_is_admin 
FROM user 
WHERE user.email = ?
 LIMIT ? OFFSET ?]
[parameters: ('hmbegham@2cconseil.com', 1, 0)]
(Background on this error at: https://sqlalche.me/e/20/e3q8)
Traceback (most recent call last):
  File "C:\Users\hmbegham\AppData\Roaming\Python\Python312\site-packages\sqlalchemy\engine\base.py", line 1965, in _exec_single_context
    self.dialect.do_execute(
  File "C:\Users\hmbegham\AppData\Roaming\Python\Python312\site-packages\sqlalchemy\engine\default.py", line 921, in do_execute
    cursor.execute(statement, parameters)
sqlite3.OperationalError: no such column: user.first_name

The above exception was the direct cause of the following exception:

Traceback (most recent call last):
  File "C:\Users\hmbegham\AppData\Roaming\Python\Python312\site-packages\flask\app.py", line 1484, in full_dispatch_request
    rv = self.dispatch_request()
         ^^^^^^^^^^^^^^^^^^^^^^^
  File "C:\Users\hmbegham\AppData\Roaming\Python\Python312\site-packages\flask\app.py", line 1469, in dispatch_request
    return self.ensure_sync(self.view_functions[rule.endpoint])(**view_args)
           ^^^^^^^^^^^^^^^^^^^^^^^^^^^^^^^^^^^^^^^^^^^^^^^^^^^^^^^^^^^^^^^^^
  File "C:\Users\hmbegham\git\employee_vote_app\app.py", line 79, in login
    user = User.query.filter_by(email=email).first()
           ^^^^^^^^^^^^^^^^^^^^^^^^^^^^^^^^^^^^^^^^^
  File "C:\Users\hmbegham\AppData\Roaming\Python\Python312\site-packages\sqlalchemy\orm\query.py", line 2743, in first
    return self.limit(1)._iter().first()  # type: ignore
           ^^^^^^^^^^^^^^^^^^^^^
  File "C:\Users\hmbegham\AppData\Roaming\Python\Python312\site-packages\sqlalchemy\orm\query.py", line 2842, in _iter
    result: Union[ScalarResult[_T], Result[_T]] = self.session.execute(
                                                  ^^^^^^^^^^^^^^^^^^^^^
  File "C:\Users\hmbegham\AppData\Roaming\Python\Python312\site-packages\sqlalchemy\orm\session.py", line 2262, in execute
    return self._execute_internal(
           ^^^^^^^^^^^^^^^^^^^^^^^
  File "C:\Users\hmbegham\AppData\Roaming\Python\Python312\site-packages\sqlalchemy\orm\session.py", line 2144, in _execute_internal
    result: Result[Any] = compile_state_cls.orm_execute_statement(
                          ^^^^^^^^^^^^^^^^^^^^^^^^^^^^^^^^^^^^^^^^
  File "C:\Users\hmbegham\AppData\Roaming\Python\Python312\site-packages\sqlalchemy\orm\context.py", line 293, in orm_execute_statement
    result = conn.execute(
             ^^^^^^^^^^^^^
  File "C:\Users\hmbegham\AppData\Roaming\Python\Python312\site-packages\sqlalchemy\engine\base.py", line 1412, in execute
    return meth(
           ^^^^^
  File "C:\Users\hmbegham\AppData\Roaming\Python\Python312\site-packages\sqlalchemy\sql\elements.py", line 516, in _execute_on_connection
    return connection._execute_clauseelement(
           ^^^^^^^^^^^^^^^^^^^^^^^^^^^^^^^^^^
  File "C:\Users\hmbegham\AppData\Roaming\Python\Python312\site-packages\sqlalchemy\engine\base.py", line 1635, in _execute_clauseelement
    ret = self._execute_context(
          ^^^^^^^^^^^^^^^^^^^^^^
  File "C:\Users\hmbegham\AppData\Roaming\Python\Python312\site-packages\sqlalchemy\engine\base.py", line 1844, in _execute_context
    return self._exec_single_context(
           ^^^^^^^^^^^^^^^^^^^^^^^^^^
  File "C:\Users\hmbegham\AppData\Roaming\Python\Python312\site-packages\sqlalchemy\engine\base.py", line 1984, in _exec_single_context
    self._handle_dbapi_exception(
  File "C:\Users\hmbegham\AppData\Roaming\Python\Python312\site-packages\sqlalchemy\engine\base.py", line 2339, in _handle_dbapi_exception
    raise sqlalchemy_exception.with_traceback(exc_info[2]) from e
  File "C:\Users\hmbegham\AppData\Roaming\Python\Python312\site-packages\sqlalchemy\engine\base.py", line 1965, in _exec_single_context
    self.dialect.do_execute(
  File "C:\Users\hmbegham\AppData\Roaming\Python\Python312\site-packages\sqlalchemy\engine\default.py", line 921, in do_execute
    cursor.execute(statement, parameters)
sqlalchemy.exc.OperationalError: (sqlite3.OperationalError) no such column: user.first_name
[SQL: SELECT user.id AS user_id, user.email AS user_email, user.name AS user_name, user.first_name AS user_first_name, user.last_name AS user_last_name, user.password_hash AS user_password_hash, user.photo_path AS user_photo_path, user.is_admin AS user_is_admin 
FROM user 
WHERE user.email = ?
 LIMIT ? OFFSET ?]
[parameters: ('hmbegham@2cconseil.com', 1, 0)]
(Background on this error at: https://sqlalche.me/e/20/e3q8)

2024-12-16 09:33:15.960486: (sqlite3.OperationalError) no such column: user.first_name
[SQL: SELECT user.id AS user_id, user.email AS user_email, user.name AS user_name, user.first_name AS user_first_name, user.last_name AS user_last_name, user.password_hash AS user_password_hash, user.photo_path AS user_photo_path, user.is_admin AS user_is_admin 
FROM user 
WHERE user.email = ?
 LIMIT ? OFFSET ?]
[parameters: ('hmbegham@2cconseil.com', 1, 0)]
(Background on this error at: https://sqlalche.me/e/20/e3q8)
Traceback (most recent call last):
  File "C:\Users\hmbegham\AppData\Roaming\Python\Python312\site-packages\sqlalchemy\engine\base.py", line 1965, in _exec_single_context
    self.dialect.do_execute(
  File "C:\Users\hmbegham\AppData\Roaming\Python\Python312\site-packages\sqlalchemy\engine\default.py", line 921, in do_execute
    cursor.execute(statement, parameters)
sqlite3.OperationalError: no such column: user.first_name

The above exception was the direct cause of the following exception:

Traceback (most recent call last):
  File "C:\Users\hmbegham\AppData\Roaming\Python\Python312\site-packages\flask\app.py", line 1484, in full_dispatch_request
    rv = self.dispatch_request()
         ^^^^^^^^^^^^^^^^^^^^^^^
  File "C:\Users\hmbegham\AppData\Roaming\Python\Python312\site-packages\flask\app.py", line 1469, in dispatch_request
    return self.ensure_sync(self.view_functions[rule.endpoint])(**view_args)
           ^^^^^^^^^^^^^^^^^^^^^^^^^^^^^^^^^^^^^^^^^^^^^^^^^^^^^^^^^^^^^^^^^
  File "C:\Users\hmbegham\git\employee_vote_app\app.py", line 79, in login
    user = User.query.filter_by(email=email).first()
           ^^^^^^^^^^^^^^^^^^^^^^^^^^^^^^^^^^^^^^^^^
  File "C:\Users\hmbegham\AppData\Roaming\Python\Python312\site-packages\sqlalchemy\orm\query.py", line 2743, in first
    return self.limit(1)._iter().first()  # type: ignore
           ^^^^^^^^^^^^^^^^^^^^^
  File "C:\Users\hmbegham\AppData\Roaming\Python\Python312\site-packages\sqlalchemy\orm\query.py", line 2842, in _iter
    result: Union[ScalarResult[_T], Result[_T]] = self.session.execute(
                                                  ^^^^^^^^^^^^^^^^^^^^^
  File "C:\Users\hmbegham\AppData\Roaming\Python\Python312\site-packages\sqlalchemy\orm\session.py", line 2262, in execute
    return self._execute_internal(
           ^^^^^^^^^^^^^^^^^^^^^^^
  File "C:\Users\hmbegham\AppData\Roaming\Python\Python312\site-packages\sqlalchemy\orm\session.py", line 2144, in _execute_internal
    result: Result[Any] = compile_state_cls.orm_execute_statement(
                          ^^^^^^^^^^^^^^^^^^^^^^^^^^^^^^^^^^^^^^^^
  File "C:\Users\hmbegham\AppData\Roaming\Python\Python312\site-packages\sqlalchemy\orm\context.py", line 293, in orm_execute_statement
    result = conn.execute(
             ^^^^^^^^^^^^^
  File "C:\Users\hmbegham\AppData\Roaming\Python\Python312\site-packages\sqlalchemy\engine\base.py", line 1412, in execute
    return meth(
           ^^^^^
  File "C:\Users\hmbegham\AppData\Roaming\Python\Python312\site-packages\sqlalchemy\sql\elements.py", line 516, in _execute_on_connection
    return connection._execute_clauseelement(
           ^^^^^^^^^^^^^^^^^^^^^^^^^^^^^^^^^^
  File "C:\Users\hmbegham\AppData\Roaming\Python\Python312\site-packages\sqlalchemy\engine\base.py", line 1635, in _execute_clauseelement
    ret = self._execute_context(
          ^^^^^^^^^^^^^^^^^^^^^^
  File "C:\Users\hmbegham\AppData\Roaming\Python\Python312\site-packages\sqlalchemy\engine\base.py", line 1844, in _execute_context
    return self._exec_single_context(
           ^^^^^^^^^^^^^^^^^^^^^^^^^^
  File "C:\Users\hmbegham\AppData\Roaming\Python\Python312\site-packages\sqlalchemy\engine\base.py", line 1984, in _exec_single_context
    self._handle_dbapi_exception(
  File "C:\Users\hmbegham\AppData\Roaming\Python\Python312\site-packages\sqlalchemy\engine\base.py", line 2339, in _handle_dbapi_exception
    raise sqlalchemy_exception.with_traceback(exc_info[2]) from e
  File "C:\Users\hmbegham\AppData\Roaming\Python\Python312\site-packages\sqlalchemy\engine\base.py", line 1965, in _exec_single_context
    self.dialect.do_execute(
  File "C:\Users\hmbegham\AppData\Roaming\Python\Python312\site-packages\sqlalchemy\engine\default.py", line 921, in do_execute
    cursor.execute(statement, parameters)
sqlalchemy.exc.OperationalError: (sqlite3.OperationalError) no such column: user.first_name
[SQL: SELECT user.id AS user_id, user.email AS user_email, user.name AS user_name, user.first_name AS user_first_name, user.last_name AS user_last_name, user.password_hash AS user_password_hash, user.photo_path AS user_photo_path, user.is_admin AS user_is_admin 
FROM user 
WHERE user.email = ?
 LIMIT ? OFFSET ?]
[parameters: ('hmbegham@2cconseil.com', 1, 0)]
(Background on this error at: https://sqlalche.me/e/20/e3q8)

2024-12-16 09:35:29.139056: (sqlite3.OperationalError) no such column: user.first_name
[SQL: SELECT user.id AS user_id, user.email AS user_email, user.name AS user_name, user.first_name AS user_first_name, user.last_name AS user_last_name, user.password_hash AS user_password_hash, user.photo_path AS user_photo_path, user.is_admin AS user_is_admin 
FROM user 
WHERE user.email = ?
 LIMIT ? OFFSET ?]
[parameters: ('hmbegham@2cconseil.com', 1, 0)]
(Background on this error at: https://sqlalche.me/e/20/e3q8)
Traceback (most recent call last):
  File "C:\Users\hmbegham\AppData\Roaming\Python\Python312\site-packages\sqlalchemy\engine\base.py", line 1965, in _exec_single_context
    self.dialect.do_execute(
  File "C:\Users\hmbegham\AppData\Roaming\Python\Python312\site-packages\sqlalchemy\engine\default.py", line 921, in do_execute
    cursor.execute(statement, parameters)
sqlite3.OperationalError: no such column: user.first_name

The above exception was the direct cause of the following exception:

Traceback (most recent call last):
  File "C:\Users\hmbegham\AppData\Roaming\Python\Python312\site-packages\flask\app.py", line 1484, in full_dispatch_request
    rv = self.dispatch_request()
         ^^^^^^^^^^^^^^^^^^^^^^^
  File "C:\Users\hmbegham\AppData\Roaming\Python\Python312\site-packages\flask\app.py", line 1469, in dispatch_request
    return self.ensure_sync(self.view_functions[rule.endpoint])(**view_args)
           ^^^^^^^^^^^^^^^^^^^^^^^^^^^^^^^^^^^^^^^^^^^^^^^^^^^^^^^^^^^^^^^^^
  File "C:\Users\hmbegham\git\employee_vote_app\app.py", line 79, in login
    user = User.query.filter_by(email=email).first()
           ^^^^^^^^^^^^^^^^^^^^^^^^^^^^^^^^^^^^^^^^^
  File "C:\Users\hmbegham\AppData\Roaming\Python\Python312\site-packages\sqlalchemy\orm\query.py", line 2743, in first
    return self.limit(1)._iter().first()  # type: ignore
           ^^^^^^^^^^^^^^^^^^^^^
  File "C:\Users\hmbegham\AppData\Roaming\Python\Python312\site-packages\sqlalchemy\orm\query.py", line 2842, in _iter
    result: Union[ScalarResult[_T], Result[_T]] = self.session.execute(
                                                  ^^^^^^^^^^^^^^^^^^^^^
  File "C:\Users\hmbegham\AppData\Roaming\Python\Python312\site-packages\sqlalchemy\orm\session.py", line 2262, in execute
    return self._execute_internal(
           ^^^^^^^^^^^^^^^^^^^^^^^
  File "C:\Users\hmbegham\AppData\Roaming\Python\Python312\site-packages\sqlalchemy\orm\session.py", line 2144, in _execute_internal
    result: Result[Any] = compile_state_cls.orm_execute_statement(
                          ^^^^^^^^^^^^^^^^^^^^^^^^^^^^^^^^^^^^^^^^
  File "C:\Users\hmbegham\AppData\Roaming\Python\Python312\site-packages\sqlalchemy\orm\context.py", line 293, in orm_execute_statement
    result = conn.execute(
             ^^^^^^^^^^^^^
  File "C:\Users\hmbegham\AppData\Roaming\Python\Python312\site-packages\sqlalchemy\engine\base.py", line 1412, in execute
    return meth(
           ^^^^^
  File "C:\Users\hmbegham\AppData\Roaming\Python\Python312\site-packages\sqlalchemy\sql\elements.py", line 516, in _execute_on_connection
    return connection._execute_clauseelement(
           ^^^^^^^^^^^^^^^^^^^^^^^^^^^^^^^^^^
  File "C:\Users\hmbegham\AppData\Roaming\Python\Python312\site-packages\sqlalchemy\engine\base.py", line 1635, in _execute_clauseelement
    ret = self._execute_context(
          ^^^^^^^^^^^^^^^^^^^^^^
  File "C:\Users\hmbegham\AppData\Roaming\Python\Python312\site-packages\sqlalchemy\engine\base.py", line 1844, in _execute_context
    return self._exec_single_context(
           ^^^^^^^^^^^^^^^^^^^^^^^^^^
  File "C:\Users\hmbegham\AppData\Roaming\Python\Python312\site-packages\sqlalchemy\engine\base.py", line 1984, in _exec_single_context
    self._handle_dbapi_exception(
  File "C:\Users\hmbegham\AppData\Roaming\Python\Python312\site-packages\sqlalchemy\engine\base.py", line 2339, in _handle_dbapi_exception
    raise sqlalchemy_exception.with_traceback(exc_info[2]) from e
  File "C:\Users\hmbegham\AppData\Roaming\Python\Python312\site-packages\sqlalchemy\engine\base.py", line 1965, in _exec_single_context
    self.dialect.do_execute(
  File "C:\Users\hmbegham\AppData\Roaming\Python\Python312\site-packages\sqlalchemy\engine\default.py", line 921, in do_execute
    cursor.execute(statement, parameters)
sqlalchemy.exc.OperationalError: (sqlite3.OperationalError) no such column: user.first_name
[SQL: SELECT user.id AS user_id, user.email AS user_email, user.name AS user_name, user.first_name AS user_first_name, user.last_name AS user_last_name, user.password_hash AS user_password_hash, user.photo_path AS user_photo_path, user.is_admin AS user_is_admin 
FROM user 
WHERE user.email = ?
 LIMIT ? OFFSET ?]
[parameters: ('hmbegham@2cconseil.com', 1, 0)]
(Background on this error at: https://sqlalche.me/e/20/e3q8)

2024-12-16 09:35:34.359707: (sqlite3.OperationalError) no such column: user.first_name
[SQL: SELECT user.id AS user_id, user.email AS user_email, user.name AS user_name, user.first_name AS user_first_name, user.last_name AS user_last_name, user.password_hash AS user_password_hash, user.photo_path AS user_photo_path, user.is_admin AS user_is_admin 
FROM user 
WHERE user.email = ?
 LIMIT ? OFFSET ?]
[parameters: ('hmbegham@2cconseil.com', 1, 0)]
(Background on this error at: https://sqlalche.me/e/20/e3q8)
Traceback (most recent call last):
  File "C:\Users\hmbegham\AppData\Roaming\Python\Python312\site-packages\sqlalchemy\engine\base.py", line 1965, in _exec_single_context
    self.dialect.do_execute(
  File "C:\Users\hmbegham\AppData\Roaming\Python\Python312\site-packages\sqlalchemy\engine\default.py", line 921, in do_execute
    cursor.execute(statement, parameters)
sqlite3.OperationalError: no such column: user.first_name

The above exception was the direct cause of the following exception:

Traceback (most recent call last):
  File "C:\Users\hmbegham\AppData\Roaming\Python\Python312\site-packages\flask\app.py", line 1484, in full_dispatch_request
    rv = self.dispatch_request()
         ^^^^^^^^^^^^^^^^^^^^^^^
  File "C:\Users\hmbegham\AppData\Roaming\Python\Python312\site-packages\flask\app.py", line 1469, in dispatch_request
    return self.ensure_sync(self.view_functions[rule.endpoint])(**view_args)
           ^^^^^^^^^^^^^^^^^^^^^^^^^^^^^^^^^^^^^^^^^^^^^^^^^^^^^^^^^^^^^^^^^
  File "C:\Users\hmbegham\git\employee_vote_app\app.py", line 79, in login
    user = User.query.filter_by(email=email).first()
           ^^^^^^^^^^^^^^^^^^^^^^^^^^^^^^^^^^^^^^^^^
  File "C:\Users\hmbegham\AppData\Roaming\Python\Python312\site-packages\sqlalchemy\orm\query.py", line 2743, in first
    return self.limit(1)._iter().first()  # type: ignore
           ^^^^^^^^^^^^^^^^^^^^^
  File "C:\Users\hmbegham\AppData\Roaming\Python\Python312\site-packages\sqlalchemy\orm\query.py", line 2842, in _iter
    result: Union[ScalarResult[_T], Result[_T]] = self.session.execute(
                                                  ^^^^^^^^^^^^^^^^^^^^^
  File "C:\Users\hmbegham\AppData\Roaming\Python\Python312\site-packages\sqlalchemy\orm\session.py", line 2262, in execute
    return self._execute_internal(
           ^^^^^^^^^^^^^^^^^^^^^^^
  File "C:\Users\hmbegham\AppData\Roaming\Python\Python312\site-packages\sqlalchemy\orm\session.py", line 2144, in _execute_internal
    result: Result[Any] = compile_state_cls.orm_execute_statement(
                          ^^^^^^^^^^^^^^^^^^^^^^^^^^^^^^^^^^^^^^^^
  File "C:\Users\hmbegham\AppData\Roaming\Python\Python312\site-packages\sqlalchemy\orm\context.py", line 293, in orm_execute_statement
    result = conn.execute(
             ^^^^^^^^^^^^^
  File "C:\Users\hmbegham\AppData\Roaming\Python\Python312\site-packages\sqlalchemy\engine\base.py", line 1412, in execute
    return meth(
           ^^^^^
  File "C:\Users\hmbegham\AppData\Roaming\Python\Python312\site-packages\sqlalchemy\sql\elements.py", line 516, in _execute_on_connection
    return connection._execute_clauseelement(
           ^^^^^^^^^^^^^^^^^^^^^^^^^^^^^^^^^^
  File "C:\Users\hmbegham\AppData\Roaming\Python\Python312\site-packages\sqlalchemy\engine\base.py", line 1635, in _execute_clauseelement
    ret = self._execute_context(
          ^^^^^^^^^^^^^^^^^^^^^^
  File "C:\Users\hmbegham\AppData\Roaming\Python\Python312\site-packages\sqlalchemy\engine\base.py", line 1844, in _execute_context
    return self._exec_single_context(
           ^^^^^^^^^^^^^^^^^^^^^^^^^^
  File "C:\Users\hmbegham\AppData\Roaming\Python\Python312\site-packages\sqlalchemy\engine\base.py", line 1984, in _exec_single_context
    self._handle_dbapi_exception(
  File "C:\Users\hmbegham\AppData\Roaming\Python\Python312\site-packages\sqlalchemy\engine\base.py", line 2339, in _handle_dbapi_exception
    raise sqlalchemy_exception.with_traceback(exc_info[2]) from e
  File "C:\Users\hmbegham\AppData\Roaming\Python\Python312\site-packages\sqlalchemy\engine\base.py", line 1965, in _exec_single_context
    self.dialect.do_execute(
  File "C:\Users\hmbegham\AppData\Roaming\Python\Python312\site-packages\sqlalchemy\engine\default.py", line 921, in do_execute
    cursor.execute(statement, parameters)
sqlalchemy.exc.OperationalError: (sqlite3.OperationalError) no such column: user.first_name
[SQL: SELECT user.id AS user_id, user.email AS user_email, user.name AS user_name, user.first_name AS user_first_name, user.last_name AS user_last_name, user.password_hash AS user_password_hash, user.photo_path AS user_photo_path, user.is_admin AS user_is_admin 
FROM user 
WHERE user.email = ?
 LIMIT ? OFFSET ?]
[parameters: ('hmbegham@2cconseil.com', 1, 0)]
(Background on this error at: https://sqlalche.me/e/20/e3q8)

2024-12-16 09:35:38.324293: (sqlite3.OperationalError) no such column: user.first_name
[SQL: SELECT user.id AS user_id, user.email AS user_email, user.name AS user_name, user.first_name AS user_first_name, user.last_name AS user_last_name, user.password_hash AS user_password_hash, user.photo_path AS user_photo_path, user.is_admin AS user_is_admin 
FROM user 
WHERE user.email = ?
 LIMIT ? OFFSET ?]
[parameters: ('hmbegham@2cconseil.com', 1, 0)]
(Background on this error at: https://sqlalche.me/e/20/e3q8)
Traceback (most recent call last):
  File "C:\Users\hmbegham\AppData\Roaming\Python\Python312\site-packages\sqlalchemy\engine\base.py", line 1965, in _exec_single_context
    self.dialect.do_execute(
  File "C:\Users\hmbegham\AppData\Roaming\Python\Python312\site-packages\sqlalchemy\engine\default.py", line 921, in do_execute
    cursor.execute(statement, parameters)
sqlite3.OperationalError: no such column: user.first_name

The above exception was the direct cause of the following exception:

Traceback (most recent call last):
  File "C:\Users\hmbegham\AppData\Roaming\Python\Python312\site-packages\flask\app.py", line 1484, in full_dispatch_request
    rv = self.dispatch_request()
         ^^^^^^^^^^^^^^^^^^^^^^^
  File "C:\Users\hmbegham\AppData\Roaming\Python\Python312\site-packages\flask\app.py", line 1469, in dispatch_request
    return self.ensure_sync(self.view_functions[rule.endpoint])(**view_args)
           ^^^^^^^^^^^^^^^^^^^^^^^^^^^^^^^^^^^^^^^^^^^^^^^^^^^^^^^^^^^^^^^^^
  File "C:\Users\hmbegham\git\employee_vote_app\app.py", line 79, in login
    user = User.query.filter_by(email=email).first()
           ^^^^^^^^^^^^^^^^^^^^^^^^^^^^^^^^^^^^^^^^^
  File "C:\Users\hmbegham\AppData\Roaming\Python\Python312\site-packages\sqlalchemy\orm\query.py", line 2743, in first
    return self.limit(1)._iter().first()  # type: ignore
           ^^^^^^^^^^^^^^^^^^^^^
  File "C:\Users\hmbegham\AppData\Roaming\Python\Python312\site-packages\sqlalchemy\orm\query.py", line 2842, in _iter
    result: Union[ScalarResult[_T], Result[_T]] = self.session.execute(
                                                  ^^^^^^^^^^^^^^^^^^^^^
  File "C:\Users\hmbegham\AppData\Roaming\Python\Python312\site-packages\sqlalchemy\orm\session.py", line 2262, in execute
    return self._execute_internal(
           ^^^^^^^^^^^^^^^^^^^^^^^
  File "C:\Users\hmbegham\AppData\Roaming\Python\Python312\site-packages\sqlalchemy\orm\session.py", line 2144, in _execute_internal
    result: Result[Any] = compile_state_cls.orm_execute_statement(
                          ^^^^^^^^^^^^^^^^^^^^^^^^^^^^^^^^^^^^^^^^
  File "C:\Users\hmbegham\AppData\Roaming\Python\Python312\site-packages\sqlalchemy\orm\context.py", line 293, in orm_execute_statement
    result = conn.execute(
             ^^^^^^^^^^^^^
  File "C:\Users\hmbegham\AppData\Roaming\Python\Python312\site-packages\sqlalchemy\engine\base.py", line 1412, in execute
    return meth(
           ^^^^^
  File "C:\Users\hmbegham\AppData\Roaming\Python\Python312\site-packages\sqlalchemy\sql\elements.py", line 516, in _execute_on_connection
    return connection._execute_clauseelement(
           ^^^^^^^^^^^^^^^^^^^^^^^^^^^^^^^^^^
  File "C:\Users\hmbegham\AppData\Roaming\Python\Python312\site-packages\sqlalchemy\engine\base.py", line 1635, in _execute_clauseelement
    ret = self._execute_context(
          ^^^^^^^^^^^^^^^^^^^^^^
  File "C:\Users\hmbegham\AppData\Roaming\Python\Python312\site-packages\sqlalchemy\engine\base.py", line 1844, in _execute_context
    return self._exec_single_context(
           ^^^^^^^^^^^^^^^^^^^^^^^^^^
  File "C:\Users\hmbegham\AppData\Roaming\Python\Python312\site-packages\sqlalchemy\engine\base.py", line 1984, in _exec_single_context
    self._handle_dbapi_exception(
  File "C:\Users\hmbegham\AppData\Roaming\Python\Python312\site-packages\sqlalchemy\engine\base.py", line 2339, in _handle_dbapi_exception
    raise sqlalchemy_exception.with_traceback(exc_info[2]) from e
  File "C:\Users\hmbegham\AppData\Roaming\Python\Python312\site-packages\sqlalchemy\engine\base.py", line 1965, in _exec_single_context
    self.dialect.do_execute(
  File "C:\Users\hmbegham\AppData\Roaming\Python\Python312\site-packages\sqlalchemy\engine\default.py", line 921, in do_execute
    cursor.execute(statement, parameters)
sqlalchemy.exc.OperationalError: (sqlite3.OperationalError) no such column: user.first_name
[SQL: SELECT user.id AS user_id, user.email AS user_email, user.name AS user_name, user.first_name AS user_first_name, user.last_name AS user_last_name, user.password_hash AS user_password_hash, user.photo_path AS user_photo_path, user.is_admin AS user_is_admin 
FROM user 
WHERE user.email = ?
 LIMIT ? OFFSET ?]
[parameters: ('hmbegham@2cconseil.com', 1, 0)]
(Background on this error at: https://sqlalche.me/e/20/e3q8)

2024-12-16 09:36:09.236470: (sqlite3.OperationalError) no such column: user.first_name
[SQL: SELECT user.id AS user_id, user.email AS user_email, user.name AS user_name, user.first_name AS user_first_name, user.last_name AS user_last_name, user.password_hash AS user_password_hash, user.photo_path AS user_photo_path, user.is_admin AS user_is_admin 
FROM user 
WHERE user.email = ?
 LIMIT ? OFFSET ?]
[parameters: ('hmbegham@2cconseil.com', 1, 0)]
(Background on this error at: https://sqlalche.me/e/20/e3q8)
Traceback (most recent call last):
  File "C:\Users\hmbegham\AppData\Roaming\Python\Python312\site-packages\sqlalchemy\engine\base.py", line 1965, in _exec_single_context
    self.dialect.do_execute(
  File "C:\Users\hmbegham\AppData\Roaming\Python\Python312\site-packages\sqlalchemy\engine\default.py", line 921, in do_execute
    cursor.execute(statement, parameters)
sqlite3.OperationalError: no such column: user.first_name

The above exception was the direct cause of the following exception:

Traceback (most recent call last):
  File "C:\Users\hmbegham\AppData\Roaming\Python\Python312\site-packages\flask\app.py", line 1484, in full_dispatch_request
    rv = self.dispatch_request()
         ^^^^^^^^^^^^^^^^^^^^^^^
  File "C:\Users\hmbegham\AppData\Roaming\Python\Python312\site-packages\flask\app.py", line 1469, in dispatch_request
    return self.ensure_sync(self.view_functions[rule.endpoint])(**view_args)
           ^^^^^^^^^^^^^^^^^^^^^^^^^^^^^^^^^^^^^^^^^^^^^^^^^^^^^^^^^^^^^^^^^
  File "C:\Users\hmbegham\git\employee_vote_app\app.py", line 79, in login
    user = User.query.filter_by(email=email).first()
           ^^^^^^^^^^^^^^^^^^^^^^^^^^^^^^^^^^^^^^^^^
  File "C:\Users\hmbegham\AppData\Roaming\Python\Python312\site-packages\sqlalchemy\orm\query.py", line 2743, in first
    return self.limit(1)._iter().first()  # type: ignore
           ^^^^^^^^^^^^^^^^^^^^^
  File "C:\Users\hmbegham\AppData\Roaming\Python\Python312\site-packages\sqlalchemy\orm\query.py", line 2842, in _iter
    result: Union[ScalarResult[_T], Result[_T]] = self.session.execute(
                                                  ^^^^^^^^^^^^^^^^^^^^^
  File "C:\Users\hmbegham\AppData\Roaming\Python\Python312\site-packages\sqlalchemy\orm\session.py", line 2262, in execute
    return self._execute_internal(
           ^^^^^^^^^^^^^^^^^^^^^^^
  File "C:\Users\hmbegham\AppData\Roaming\Python\Python312\site-packages\sqlalchemy\orm\session.py", line 2144, in _execute_internal
    result: Result[Any] = compile_state_cls.orm_execute_statement(
                          ^^^^^^^^^^^^^^^^^^^^^^^^^^^^^^^^^^^^^^^^
  File "C:\Users\hmbegham\AppData\Roaming\Python\Python312\site-packages\sqlalchemy\orm\context.py", line 293, in orm_execute_statement
    result = conn.execute(
             ^^^^^^^^^^^^^
  File "C:\Users\hmbegham\AppData\Roaming\Python\Python312\site-packages\sqlalchemy\engine\base.py", line 1412, in execute
    return meth(
           ^^^^^
  File "C:\Users\hmbegham\AppData\Roaming\Python\Python312\site-packages\sqlalchemy\sql\elements.py", line 516, in _execute_on_connection
    return connection._execute_clauseelement(
           ^^^^^^^^^^^^^^^^^^^^^^^^^^^^^^^^^^
  File "C:\Users\hmbegham\AppData\Roaming\Python\Python312\site-packages\sqlalchemy\engine\base.py", line 1635, in _execute_clauseelement
    ret = self._execute_context(
          ^^^^^^^^^^^^^^^^^^^^^^
  File "C:\Users\hmbegham\AppData\Roaming\Python\Python312\site-packages\sqlalchemy\engine\base.py", line 1844, in _execute_context
    return self._exec_single_context(
           ^^^^^^^^^^^^^^^^^^^^^^^^^^
  File "C:\Users\hmbegham\AppData\Roaming\Python\Python312\site-packages\sqlalchemy\engine\base.py", line 1984, in _exec_single_context
    self._handle_dbapi_exception(
  File "C:\Users\hmbegham\AppData\Roaming\Python\Python312\site-packages\sqlalchemy\engine\base.py", line 2339, in _handle_dbapi_exception
    raise sqlalchemy_exception.with_traceback(exc_info[2]) from e
  File "C:\Users\hmbegham\AppData\Roaming\Python\Python312\site-packages\sqlalchemy\engine\base.py", line 1965, in _exec_single_context
    self.dialect.do_execute(
  File "C:\Users\hmbegham\AppData\Roaming\Python\Python312\site-packages\sqlalchemy\engine\default.py", line 921, in do_execute
    cursor.execute(statement, parameters)
sqlalchemy.exc.OperationalError: (sqlite3.OperationalError) no such column: user.first_name
[SQL: SELECT user.id AS user_id, user.email AS user_email, user.name AS user_name, user.first_name AS user_first_name, user.last_name AS user_last_name, user.password_hash AS user_password_hash, user.photo_path AS user_photo_path, user.is_admin AS user_is_admin 
FROM user 
WHERE user.email = ?
 LIMIT ? OFFSET ?]
[parameters: ('hmbegham@2cconseil.com', 1, 0)]
(Background on this error at: https://sqlalche.me/e/20/e3q8)

2024-12-16 09:36:42.128226: (sqlite3.OperationalError) no such column: user.first_name
[SQL: SELECT user.id AS user_id, user.email AS user_email, user.name AS user_name, user.first_name AS user_first_name, user.last_name AS user_last_name, user.password_hash AS user_password_hash, user.photo_path AS user_photo_path, user.is_admin AS user_is_admin 
FROM user 
WHERE user.email = ?
 LIMIT ? OFFSET ?]
[parameters: ('hmbegham@2cconseil.com', 1, 0)]
(Background on this error at: https://sqlalche.me/e/20/e3q8)
Traceback (most recent call last):
  File "C:\Users\hmbegham\AppData\Roaming\Python\Python312\site-packages\sqlalchemy\engine\base.py", line 1965, in _exec_single_context
    self.dialect.do_execute(
  File "C:\Users\hmbegham\AppData\Roaming\Python\Python312\site-packages\sqlalchemy\engine\default.py", line 921, in do_execute
    cursor.execute(statement, parameters)
sqlite3.OperationalError: no such column: user.first_name

The above exception was the direct cause of the following exception:

Traceback (most recent call last):
  File "C:\Users\hmbegham\AppData\Roaming\Python\Python312\site-packages\flask\app.py", line 1484, in full_dispatch_request
    rv = self.dispatch_request()
         ^^^^^^^^^^^^^^^^^^^^^^^
  File "C:\Users\hmbegham\AppData\Roaming\Python\Python312\site-packages\flask\app.py", line 1469, in dispatch_request
    return self.ensure_sync(self.view_functions[rule.endpoint])(**view_args)
           ^^^^^^^^^^^^^^^^^^^^^^^^^^^^^^^^^^^^^^^^^^^^^^^^^^^^^^^^^^^^^^^^^
  File "C:\Users\hmbegham\git\employee_vote_app\app.py", line 79, in login
    user = User.query.filter_by(email=email).first()
           ^^^^^^^^^^^^^^^^^^^^^^^^^^^^^^^^^^^^^^^^^
  File "C:\Users\hmbegham\AppData\Roaming\Python\Python312\site-packages\sqlalchemy\orm\query.py", line 2743, in first
    return self.limit(1)._iter().first()  # type: ignore
           ^^^^^^^^^^^^^^^^^^^^^
  File "C:\Users\hmbegham\AppData\Roaming\Python\Python312\site-packages\sqlalchemy\orm\query.py", line 2842, in _iter
    result: Union[ScalarResult[_T], Result[_T]] = self.session.execute(
                                                  ^^^^^^^^^^^^^^^^^^^^^
  File "C:\Users\hmbegham\AppData\Roaming\Python\Python312\site-packages\sqlalchemy\orm\session.py", line 2262, in execute
    return self._execute_internal(
           ^^^^^^^^^^^^^^^^^^^^^^^
  File "C:\Users\hmbegham\AppData\Roaming\Python\Python312\site-packages\sqlalchemy\orm\session.py", line 2144, in _execute_internal
    result: Result[Any] = compile_state_cls.orm_execute_statement(
                          ^^^^^^^^^^^^^^^^^^^^^^^^^^^^^^^^^^^^^^^^
  File "C:\Users\hmbegham\AppData\Roaming\Python\Python312\site-packages\sqlalchemy\orm\context.py", line 293, in orm_execute_statement
    result = conn.execute(
             ^^^^^^^^^^^^^
  File "C:\Users\hmbegham\AppData\Roaming\Python\Python312\site-packages\sqlalchemy\engine\base.py", line 1412, in execute
    return meth(
           ^^^^^
  File "C:\Users\hmbegham\AppData\Roaming\Python\Python312\site-packages\sqlalchemy\sql\elements.py", line 516, in _execute_on_connection
    return connection._execute_clauseelement(
           ^^^^^^^^^^^^^^^^^^^^^^^^^^^^^^^^^^
  File "C:\Users\hmbegham\AppData\Roaming\Python\Python312\site-packages\sqlalchemy\engine\base.py", line 1635, in _execute_clauseelement
    ret = self._execute_context(
          ^^^^^^^^^^^^^^^^^^^^^^
  File "C:\Users\hmbegham\AppData\Roaming\Python\Python312\site-packages\sqlalchemy\engine\base.py", line 1844, in _execute_context
    return self._exec_single_context(
           ^^^^^^^^^^^^^^^^^^^^^^^^^^
  File "C:\Users\hmbegham\AppData\Roaming\Python\Python312\site-packages\sqlalchemy\engine\base.py", line 1984, in _exec_single_context
    self._handle_dbapi_exception(
  File "C:\Users\hmbegham\AppData\Roaming\Python\Python312\site-packages\sqlalchemy\engine\base.py", line 2339, in _handle_dbapi_exception
    raise sqlalchemy_exception.with_traceback(exc_info[2]) from e
  File "C:\Users\hmbegham\AppData\Roaming\Python\Python312\site-packages\sqlalchemy\engine\base.py", line 1965, in _exec_single_context
    self.dialect.do_execute(
  File "C:\Users\hmbegham\AppData\Roaming\Python\Python312\site-packages\sqlalchemy\engine\default.py", line 921, in do_execute
    cursor.execute(statement, parameters)
sqlalchemy.exc.OperationalError: (sqlite3.OperationalError) no such column: user.first_name
[SQL: SELECT user.id AS user_id, user.email AS user_email, user.name AS user_name, user.first_name AS user_first_name, user.last_name AS user_last_name, user.password_hash AS user_password_hash, user.photo_path AS user_photo_path, user.is_admin AS user_is_admin 
FROM user 
WHERE user.email = ?
 LIMIT ? OFFSET ?]
[parameters: ('hmbegham@2cconseil.com', 1, 0)]
(Background on this error at: https://sqlalche.me/e/20/e3q8)

2024-12-16 09:36:47.796908: 404 Not Found: The requested URL was not found on the server. If you entered the URL manually please check your spelling and try again.
Traceback (most recent call last):
  File "C:\Users\hmbegham\AppData\Roaming\Python\Python312\site-packages\flask\app.py", line 1484, in full_dispatch_request
    rv = self.dispatch_request()
         ^^^^^^^^^^^^^^^^^^^^^^^
  File "C:\Users\hmbegham\AppData\Roaming\Python\Python312\site-packages\flask\app.py", line 1458, in dispatch_request
    self.raise_routing_exception(req)
  File "C:\Users\hmbegham\AppData\Roaming\Python\Python312\site-packages\flask\app.py", line 1440, in raise_routing_exception
    raise request.routing_exception  # type: ignore
    ^^^^^^^^^^^^^^^^^^^^^^^^^^^^^^^
  File "C:\Users\hmbegham\AppData\Roaming\Python\Python312\site-packages\flask\ctx.py", line 353, in match_request
    result = self.url_adapter.match(return_rule=True)  # type: ignore
             ^^^^^^^^^^^^^^^^^^^^^^^^^^^^^^^^^^^^^^^^
  File "C:\Users\hmbegham\AppData\Roaming\Python\Python312\site-packages\werkzeug\routing\map.py", line 655, in match
    raise NotFound() from None
werkzeug.exceptions.NotFound: 404 Not Found: The requested URL was not found on the server. If you entered the URL manually please check your spelling and try again.

2024-12-16 09:36:57.276179: (sqlite3.OperationalError) no such column: user.first_name
[SQL: SELECT user.id AS user_id, user.email AS user_email, user.name AS user_name, user.first_name AS user_first_name, user.last_name AS user_last_name, user.password_hash AS user_password_hash, user.photo_path AS user_photo_path, user.is_admin AS user_is_admin 
FROM user 
WHERE user.email = ?
 LIMIT ? OFFSET ?]
[parameters: ('hmbegham@2cconseil.com', 1, 0)]
(Background on this error at: https://sqlalche.me/e/20/e3q8)
Traceback (most recent call last):
  File "C:\Users\hmbegham\AppData\Roaming\Python\Python312\site-packages\sqlalchemy\engine\base.py", line 1965, in _exec_single_context
    self.dialect.do_execute(
  File "C:\Users\hmbegham\AppData\Roaming\Python\Python312\site-packages\sqlalchemy\engine\default.py", line 921, in do_execute
    cursor.execute(statement, parameters)
sqlite3.OperationalError: no such column: user.first_name

The above exception was the direct cause of the following exception:

Traceback (most recent call last):
  File "C:\Users\hmbegham\AppData\Roaming\Python\Python312\site-packages\flask\app.py", line 1484, in full_dispatch_request
    rv = self.dispatch_request()
         ^^^^^^^^^^^^^^^^^^^^^^^
  File "C:\Users\hmbegham\AppData\Roaming\Python\Python312\site-packages\flask\app.py", line 1469, in dispatch_request
    return self.ensure_sync(self.view_functions[rule.endpoint])(**view_args)
           ^^^^^^^^^^^^^^^^^^^^^^^^^^^^^^^^^^^^^^^^^^^^^^^^^^^^^^^^^^^^^^^^^
  File "C:\Users\hmbegham\git\employee_vote_app\app.py", line 79, in login
    user = User.query.filter_by(email=email).first()
           ^^^^^^^^^^^^^^^^^^^^^^^^^^^^^^^^^^^^^^^^^
  File "C:\Users\hmbegham\AppData\Roaming\Python\Python312\site-packages\sqlalchemy\orm\query.py", line 2743, in first
    return self.limit(1)._iter().first()  # type: ignore
           ^^^^^^^^^^^^^^^^^^^^^
  File "C:\Users\hmbegham\AppData\Roaming\Python\Python312\site-packages\sqlalchemy\orm\query.py", line 2842, in _iter
    result: Union[ScalarResult[_T], Result[_T]] = self.session.execute(
                                                  ^^^^^^^^^^^^^^^^^^^^^
  File "C:\Users\hmbegham\AppData\Roaming\Python\Python312\site-packages\sqlalchemy\orm\session.py", line 2262, in execute
    return self._execute_internal(
           ^^^^^^^^^^^^^^^^^^^^^^^
  File "C:\Users\hmbegham\AppData\Roaming\Python\Python312\site-packages\sqlalchemy\orm\session.py", line 2144, in _execute_internal
    result: Result[Any] = compile_state_cls.orm_execute_statement(
                          ^^^^^^^^^^^^^^^^^^^^^^^^^^^^^^^^^^^^^^^^
  File "C:\Users\hmbegham\AppData\Roaming\Python\Python312\site-packages\sqlalchemy\orm\context.py", line 293, in orm_execute_statement
    result = conn.execute(
             ^^^^^^^^^^^^^
  File "C:\Users\hmbegham\AppData\Roaming\Python\Python312\site-packages\sqlalchemy\engine\base.py", line 1412, in execute
    return meth(
           ^^^^^
  File "C:\Users\hmbegham\AppData\Roaming\Python\Python312\site-packages\sqlalchemy\sql\elements.py", line 516, in _execute_on_connection
    return connection._execute_clauseelement(
           ^^^^^^^^^^^^^^^^^^^^^^^^^^^^^^^^^^
  File "C:\Users\hmbegham\AppData\Roaming\Python\Python312\site-packages\sqlalchemy\engine\base.py", line 1635, in _execute_clauseelement
    ret = self._execute_context(
          ^^^^^^^^^^^^^^^^^^^^^^
  File "C:\Users\hmbegham\AppData\Roaming\Python\Python312\site-packages\sqlalchemy\engine\base.py", line 1844, in _execute_context
    return self._exec_single_context(
           ^^^^^^^^^^^^^^^^^^^^^^^^^^
  File "C:\Users\hmbegham\AppData\Roaming\Python\Python312\site-packages\sqlalchemy\engine\base.py", line 1984, in _exec_single_context
    self._handle_dbapi_exception(
  File "C:\Users\hmbegham\AppData\Roaming\Python\Python312\site-packages\sqlalchemy\engine\base.py", line 2339, in _handle_dbapi_exception
    raise sqlalchemy_exception.with_traceback(exc_info[2]) from e
  File "C:\Users\hmbegham\AppData\Roaming\Python\Python312\site-packages\sqlalchemy\engine\base.py", line 1965, in _exec_single_context
    self.dialect.do_execute(
  File "C:\Users\hmbegham\AppData\Roaming\Python\Python312\site-packages\sqlalchemy\engine\default.py", line 921, in do_execute
    cursor.execute(statement, parameters)
sqlalchemy.exc.OperationalError: (sqlite3.OperationalError) no such column: user.first_name
[SQL: SELECT user.id AS user_id, user.email AS user_email, user.name AS user_name, user.first_name AS user_first_name, user.last_name AS user_last_name, user.password_hash AS user_password_hash, user.photo_path AS user_photo_path, user.is_admin AS user_is_admin 
FROM user 
WHERE user.email = ?
 LIMIT ? OFFSET ?]
[parameters: ('hmbegham@2cconseil.com', 1, 0)]
(Background on this error at: https://sqlalche.me/e/20/e3q8)

2024-12-16 09:53:27.573708: (sqlite3.OperationalError) no such column: user.first_name
[SQL: SELECT user.id AS user_id, user.email AS user_email, user.name AS user_name, user.first_name AS user_first_name, user.last_name AS user_last_name, user.password_hash AS user_password_hash, user.photo_path AS user_photo_path, user.is_admin AS user_is_admin 
FROM user 
WHERE user.email = ?
 LIMIT ? OFFSET ?]
[parameters: ('hmbegham@2cconseil.com', 1, 0)]
(Background on this error at: https://sqlalche.me/e/20/e3q8)
Traceback (most recent call last):
  File "C:\Users\hmbegham\AppData\Roaming\Python\Python312\site-packages\sqlalchemy\engine\base.py", line 1965, in _exec_single_context
    self.dialect.do_execute(
  File "C:\Users\hmbegham\AppData\Roaming\Python\Python312\site-packages\sqlalchemy\engine\default.py", line 921, in do_execute
    cursor.execute(statement, parameters)
sqlite3.OperationalError: no such column: user.first_name

The above exception was the direct cause of the following exception:

Traceback (most recent call last):
  File "C:\Users\hmbegham\AppData\Roaming\Python\Python312\site-packages\flask\app.py", line 1484, in full_dispatch_request
    rv = self.dispatch_request()
         ^^^^^^^^^^^^^^^^^^^^^^^
  File "C:\Users\hmbegham\AppData\Roaming\Python\Python312\site-packages\flask\app.py", line 1469, in dispatch_request
    return self.ensure_sync(self.view_functions[rule.endpoint])(**view_args)
           ^^^^^^^^^^^^^^^^^^^^^^^^^^^^^^^^^^^^^^^^^^^^^^^^^^^^^^^^^^^^^^^^^
  File "C:\Users\hmbegham\git\employee_vote_app\app.py", line 79, in login
    user = User.query.filter_by(email=email).first()
           ^^^^^^^^^^^^^^^^^^^^^^^^^^^^^^^^^^^^^^^^^
  File "C:\Users\hmbegham\AppData\Roaming\Python\Python312\site-packages\sqlalchemy\orm\query.py", line 2743, in first
    return self.limit(1)._iter().first()  # type: ignore
           ^^^^^^^^^^^^^^^^^^^^^
  File "C:\Users\hmbegham\AppData\Roaming\Python\Python312\site-packages\sqlalchemy\orm\query.py", line 2842, in _iter
    result: Union[ScalarResult[_T], Result[_T]] = self.session.execute(
                                                  ^^^^^^^^^^^^^^^^^^^^^
  File "C:\Users\hmbegham\AppData\Roaming\Python\Python312\site-packages\sqlalchemy\orm\session.py", line 2262, in execute
    return self._execute_internal(
           ^^^^^^^^^^^^^^^^^^^^^^^
  File "C:\Users\hmbegham\AppData\Roaming\Python\Python312\site-packages\sqlalchemy\orm\session.py", line 2144, in _execute_internal
    result: Result[Any] = compile_state_cls.orm_execute_statement(
                          ^^^^^^^^^^^^^^^^^^^^^^^^^^^^^^^^^^^^^^^^
  File "C:\Users\hmbegham\AppData\Roaming\Python\Python312\site-packages\sqlalchemy\orm\context.py", line 293, in orm_execute_statement
    result = conn.execute(
             ^^^^^^^^^^^^^
  File "C:\Users\hmbegham\AppData\Roaming\Python\Python312\site-packages\sqlalchemy\engine\base.py", line 1412, in execute
    return meth(
           ^^^^^
  File "C:\Users\hmbegham\AppData\Roaming\Python\Python312\site-packages\sqlalchemy\sql\elements.py", line 516, in _execute_on_connection
    return connection._execute_clauseelement(
           ^^^^^^^^^^^^^^^^^^^^^^^^^^^^^^^^^^
  File "C:\Users\hmbegham\AppData\Roaming\Python\Python312\site-packages\sqlalchemy\engine\base.py", line 1635, in _execute_clauseelement
    ret = self._execute_context(
          ^^^^^^^^^^^^^^^^^^^^^^
  File "C:\Users\hmbegham\AppData\Roaming\Python\Python312\site-packages\sqlalchemy\engine\base.py", line 1844, in _execute_context
    return self._exec_single_context(
           ^^^^^^^^^^^^^^^^^^^^^^^^^^
  File "C:\Users\hmbegham\AppData\Roaming\Python\Python312\site-packages\sqlalchemy\engine\base.py", line 1984, in _exec_single_context
    self._handle_dbapi_exception(
  File "C:\Users\hmbegham\AppData\Roaming\Python\Python312\site-packages\sqlalchemy\engine\base.py", line 2339, in _handle_dbapi_exception
    raise sqlalchemy_exception.with_traceback(exc_info[2]) from e
  File "C:\Users\hmbegham\AppData\Roaming\Python\Python312\site-packages\sqlalchemy\engine\base.py", line 1965, in _exec_single_context
    self.dialect.do_execute(
  File "C:\Users\hmbegham\AppData\Roaming\Python\Python312\site-packages\sqlalchemy\engine\default.py", line 921, in do_execute
    cursor.execute(statement, parameters)
sqlalchemy.exc.OperationalError: (sqlite3.OperationalError) no such column: user.first_name
[SQL: SELECT user.id AS user_id, user.email AS user_email, user.name AS user_name, user.first_name AS user_first_name, user.last_name AS user_last_name, user.password_hash AS user_password_hash, user.photo_path AS user_photo_path, user.is_admin AS user_is_admin 
FROM user 
WHERE user.email = ?
 LIMIT ? OFFSET ?]
[parameters: ('hmbegham@2cconseil.com', 1, 0)]
(Background on this error at: https://sqlalche.me/e/20/e3q8)

2024-12-16 09:53:32.630959: (sqlite3.OperationalError) no such column: user.first_name
[SQL: SELECT user.id AS user_id, user.email AS user_email, user.name AS user_name, user.first_name AS user_first_name, user.last_name AS user_last_name, user.password_hash AS user_password_hash, user.photo_path AS user_photo_path, user.is_admin AS user_is_admin 
FROM user 
WHERE user.email = ?
 LIMIT ? OFFSET ?]
[parameters: ('hmbegham@2cconseil.com', 1, 0)]
(Background on this error at: https://sqlalche.me/e/20/e3q8)
Traceback (most recent call last):
  File "C:\Users\hmbegham\AppData\Roaming\Python\Python312\site-packages\sqlalchemy\engine\base.py", line 1965, in _exec_single_context
    self.dialect.do_execute(
  File "C:\Users\hmbegham\AppData\Roaming\Python\Python312\site-packages\sqlalchemy\engine\default.py", line 921, in do_execute
    cursor.execute(statement, parameters)
sqlite3.OperationalError: no such column: user.first_name

The above exception was the direct cause of the following exception:

Traceback (most recent call last):
  File "C:\Users\hmbegham\AppData\Roaming\Python\Python312\site-packages\flask\app.py", line 1484, in full_dispatch_request
    rv = self.dispatch_request()
         ^^^^^^^^^^^^^^^^^^^^^^^
  File "C:\Users\hmbegham\AppData\Roaming\Python\Python312\site-packages\flask\app.py", line 1469, in dispatch_request
    return self.ensure_sync(self.view_functions[rule.endpoint])(**view_args)
           ^^^^^^^^^^^^^^^^^^^^^^^^^^^^^^^^^^^^^^^^^^^^^^^^^^^^^^^^^^^^^^^^^
  File "C:\Users\hmbegham\git\employee_vote_app\app.py", line 79, in login
    user = User.query.filter_by(email=email).first()
           ^^^^^^^^^^^^^^^^^^^^^^^^^^^^^^^^^^^^^^^^^
  File "C:\Users\hmbegham\AppData\Roaming\Python\Python312\site-packages\sqlalchemy\orm\query.py", line 2743, in first
    return self.limit(1)._iter().first()  # type: ignore
           ^^^^^^^^^^^^^^^^^^^^^
  File "C:\Users\hmbegham\AppData\Roaming\Python\Python312\site-packages\sqlalchemy\orm\query.py", line 2842, in _iter
    result: Union[ScalarResult[_T], Result[_T]] = self.session.execute(
                                                  ^^^^^^^^^^^^^^^^^^^^^
  File "C:\Users\hmbegham\AppData\Roaming\Python\Python312\site-packages\sqlalchemy\orm\session.py", line 2262, in execute
    return self._execute_internal(
           ^^^^^^^^^^^^^^^^^^^^^^^
  File "C:\Users\hmbegham\AppData\Roaming\Python\Python312\site-packages\sqlalchemy\orm\session.py", line 2144, in _execute_internal
    result: Result[Any] = compile_state_cls.orm_execute_statement(
                          ^^^^^^^^^^^^^^^^^^^^^^^^^^^^^^^^^^^^^^^^
  File "C:\Users\hmbegham\AppData\Roaming\Python\Python312\site-packages\sqlalchemy\orm\context.py", line 293, in orm_execute_statement
    result = conn.execute(
             ^^^^^^^^^^^^^
  File "C:\Users\hmbegham\AppData\Roaming\Python\Python312\site-packages\sqlalchemy\engine\base.py", line 1412, in execute
    return meth(
           ^^^^^
  File "C:\Users\hmbegham\AppData\Roaming\Python\Python312\site-packages\sqlalchemy\sql\elements.py", line 516, in _execute_on_connection
    return connection._execute_clauseelement(
           ^^^^^^^^^^^^^^^^^^^^^^^^^^^^^^^^^^
  File "C:\Users\hmbegham\AppData\Roaming\Python\Python312\site-packages\sqlalchemy\engine\base.py", line 1635, in _execute_clauseelement
    ret = self._execute_context(
          ^^^^^^^^^^^^^^^^^^^^^^
  File "C:\Users\hmbegham\AppData\Roaming\Python\Python312\site-packages\sqlalchemy\engine\base.py", line 1844, in _execute_context
    return self._exec_single_context(
           ^^^^^^^^^^^^^^^^^^^^^^^^^^
  File "C:\Users\hmbegham\AppData\Roaming\Python\Python312\site-packages\sqlalchemy\engine\base.py", line 1984, in _exec_single_context
    self._handle_dbapi_exception(
  File "C:\Users\hmbegham\AppData\Roaming\Python\Python312\site-packages\sqlalchemy\engine\base.py", line 2339, in _handle_dbapi_exception
    raise sqlalchemy_exception.with_traceback(exc_info[2]) from e
  File "C:\Users\hmbegham\AppData\Roaming\Python\Python312\site-packages\sqlalchemy\engine\base.py", line 1965, in _exec_single_context
    self.dialect.do_execute(
  File "C:\Users\hmbegham\AppData\Roaming\Python\Python312\site-packages\sqlalchemy\engine\default.py", line 921, in do_execute
    cursor.execute(statement, parameters)
sqlalchemy.exc.OperationalError: (sqlite3.OperationalError) no such column: user.first_name
[SQL: SELECT user.id AS user_id, user.email AS user_email, user.name AS user_name, user.first_name AS user_first_name, user.last_name AS user_last_name, user.password_hash AS user_password_hash, user.photo_path AS user_photo_path, user.is_admin AS user_is_admin 
FROM user 
WHERE user.email = ?
 LIMIT ? OFFSET ?]
[parameters: ('hmbegham@2cconseil.com', 1, 0)]
(Background on this error at: https://sqlalche.me/e/20/e3q8)

2024-12-16 09:54:14.172073: (sqlite3.OperationalError) no such column: user.first_name
[SQL: SELECT user.id AS user_id, user.email AS user_email, user.name AS user_name, user.first_name AS user_first_name, user.last_name AS user_last_name, user.password_hash AS user_password_hash, user.photo_path AS user_photo_path, user.is_admin AS user_is_admin 
FROM user 
WHERE user.email = ?
 LIMIT ? OFFSET ?]
[parameters: ('hmbegham@2cconseil.com', 1, 0)]
(Background on this error at: https://sqlalche.me/e/20/e3q8)
Traceback (most recent call last):
  File "C:\Users\hmbegham\AppData\Roaming\Python\Python312\site-packages\sqlalchemy\engine\base.py", line 1965, in _exec_single_context
    self.dialect.do_execute(
  File "C:\Users\hmbegham\AppData\Roaming\Python\Python312\site-packages\sqlalchemy\engine\default.py", line 921, in do_execute
    cursor.execute(statement, parameters)
sqlite3.OperationalError: no such column: user.first_name

The above exception was the direct cause of the following exception:

Traceback (most recent call last):
  File "C:\Users\hmbegham\AppData\Roaming\Python\Python312\site-packages\flask\app.py", line 1484, in full_dispatch_request
    rv = self.dispatch_request()
         ^^^^^^^^^^^^^^^^^^^^^^^
  File "C:\Users\hmbegham\AppData\Roaming\Python\Python312\site-packages\flask\app.py", line 1469, in dispatch_request
    return self.ensure_sync(self.view_functions[rule.endpoint])(**view_args)
           ^^^^^^^^^^^^^^^^^^^^^^^^^^^^^^^^^^^^^^^^^^^^^^^^^^^^^^^^^^^^^^^^^
  File "C:\Users\hmbegham\git\employee_vote_app\app.py", line 79, in login
    user = User.query.filter_by(email=email).first()
           ^^^^^^^^^^^^^^^^^^^^^^^^^^^^^^^^^^^^^^^^^
  File "C:\Users\hmbegham\AppData\Roaming\Python\Python312\site-packages\sqlalchemy\orm\query.py", line 2743, in first
    return self.limit(1)._iter().first()  # type: ignore
           ^^^^^^^^^^^^^^^^^^^^^
  File "C:\Users\hmbegham\AppData\Roaming\Python\Python312\site-packages\sqlalchemy\orm\query.py", line 2842, in _iter
    result: Union[ScalarResult[_T], Result[_T]] = self.session.execute(
                                                  ^^^^^^^^^^^^^^^^^^^^^
  File "C:\Users\hmbegham\AppData\Roaming\Python\Python312\site-packages\sqlalchemy\orm\session.py", line 2262, in execute
    return self._execute_internal(
           ^^^^^^^^^^^^^^^^^^^^^^^
  File "C:\Users\hmbegham\AppData\Roaming\Python\Python312\site-packages\sqlalchemy\orm\session.py", line 2144, in _execute_internal
    result: Result[Any] = compile_state_cls.orm_execute_statement(
                          ^^^^^^^^^^^^^^^^^^^^^^^^^^^^^^^^^^^^^^^^
  File "C:\Users\hmbegham\AppData\Roaming\Python\Python312\site-packages\sqlalchemy\orm\context.py", line 293, in orm_execute_statement
    result = conn.execute(
             ^^^^^^^^^^^^^
  File "C:\Users\hmbegham\AppData\Roaming\Python\Python312\site-packages\sqlalchemy\engine\base.py", line 1412, in execute
    return meth(
           ^^^^^
  File "C:\Users\hmbegham\AppData\Roaming\Python\Python312\site-packages\sqlalchemy\sql\elements.py", line 516, in _execute_on_connection
    return connection._execute_clauseelement(
           ^^^^^^^^^^^^^^^^^^^^^^^^^^^^^^^^^^
  File "C:\Users\hmbegham\AppData\Roaming\Python\Python312\site-packages\sqlalchemy\engine\base.py", line 1635, in _execute_clauseelement
    ret = self._execute_context(
          ^^^^^^^^^^^^^^^^^^^^^^
  File "C:\Users\hmbegham\AppData\Roaming\Python\Python312\site-packages\sqlalchemy\engine\base.py", line 1844, in _execute_context
    return self._exec_single_context(
           ^^^^^^^^^^^^^^^^^^^^^^^^^^
  File "C:\Users\hmbegham\AppData\Roaming\Python\Python312\site-packages\sqlalchemy\engine\base.py", line 1984, in _exec_single_context
    self._handle_dbapi_exception(
  File "C:\Users\hmbegham\AppData\Roaming\Python\Python312\site-packages\sqlalchemy\engine\base.py", line 2339, in _handle_dbapi_exception
    raise sqlalchemy_exception.with_traceback(exc_info[2]) from e
  File "C:\Users\hmbegham\AppData\Roaming\Python\Python312\site-packages\sqlalchemy\engine\base.py", line 1965, in _exec_single_context
    self.dialect.do_execute(
  File "C:\Users\hmbegham\AppData\Roaming\Python\Python312\site-packages\sqlalchemy\engine\default.py", line 921, in do_execute
    cursor.execute(statement, parameters)
sqlalchemy.exc.OperationalError: (sqlite3.OperationalError) no such column: user.first_name
[SQL: SELECT user.id AS user_id, user.email AS user_email, user.name AS user_name, user.first_name AS user_first_name, user.last_name AS user_last_name, user.password_hash AS user_password_hash, user.photo_path AS user_photo_path, user.is_admin AS user_is_admin 
FROM user 
WHERE user.email = ?
 LIMIT ? OFFSET ?]
[parameters: ('hmbegham@2cconseil.com', 1, 0)]
(Background on this error at: https://sqlalche.me/e/20/e3q8)
